<?xml version="1.0"?>
<robot name="xarm6" path="../Arm_CDF_Planning/xarm_pybullet/xarm_description/robot.urdf">
	<gazebo>
		<plugin filename="libgazebo_ros_control.so" name="gazebo_ros_control">
			<robotNamespace>/xarm</robotNamespace>
			<robotSimType>gazebo_ros_control/DefaultRobotHWSim</robotSimType>
			<legacyModeNS>true</legacyModeNS>
		</plugin>
	</gazebo>
	<gazebo reference="link_base">
		<selfCollide>true</selfCollide>
	</gazebo>
	<gazebo reference="link1">
		<selfCollide>true</selfCollide>
	</gazebo>
	<gazebo reference="link2">
		<selfCollide>true</selfCollide>
	</gazebo>
	<gazebo reference="link3">
		<selfCollide>true</selfCollide>
	</gazebo>
	<gazebo reference="link4">
		<selfCollide>true</selfCollide>
	</gazebo>
	<gazebo reference="link5">
		<selfCollide>true</selfCollide>
	</gazebo>
	<gazebo reference="link6">
		<selfCollide>true</selfCollide>
	</gazebo>
	<link name="link_base">
		<visual>
			<geometry>
				<mesh filename="package://meshes/xarm6/visual/base.stl"></mesh>
			</geometry>
			<origin rpy="0 0 0" xyz="0 0 0"></origin>
			<material name="Blue"></material>
		</visual>
		<collision>
			<geometry>
				<sphere radius="0.091773"></sphere>
			</geometry>
			<origin xyz="-0.010778460829255994 -0.0006939764304893521 0.04639286832066155" rpy="0 0 0"></origin>
		</collision>
		<collision>
			<geometry>
				<sphere radius="0.071149"></sphere>
			</geometry>
			<origin xyz="0.0009465391707440055 0.00021702356951064784 0.11210286832066155" rpy="0 0 0"></origin>
		</collision>
		<inertial>
			<origin rpy="0 0 0" xyz="0.0 0.0 0.09103"></origin>
			<mass value="2.7"></mass>
			<inertia ixx="0.00494875" ixy="-3.5E-06" ixz="1.25E-05" iyy="0.00494174" iyz="1.67E-06" izz="0.002219"></inertia>
		</inertial>
	</link>
	<link name="link1">
		<visual>
			<geometry>
				<mesh filename="package://meshes/xarm6/visual/link1.stl"></mesh>
			</geometry>
			<origin rpy="0 0 0" xyz="0 0 0"></origin>
			<material name="Red"></material>
		</visual>
		<collision>
			<geometry>
				<sphere radius="0.075041"></sphere>
			</geometry>
			<origin xyz="-0.0001848310869140017 -0.004124202864218076 -0.0654132969136603" rpy="0 0 0"></origin>
		</collision>
		<collision>
			<geometry>
				<sphere radius="0.08223"></sphere>
			</geometry>
			<origin xyz="5.716891308599827e-05 0.016914797135781923 -0.0008532969136602966" rpy="0 0 0"></origin>
		</collision>
		<inertial>
			<origin rpy="0 0 0" xyz="-0.002 0.02692 -0.01332"></origin>
			<mass value="2.16"></mass>
			<inertia ixx="0.00539427" ixy="1.095E-05" ixz="1.635E-06" iyy="0.0048979" iyz="0.000793" izz="0.00311573"></inertia>
		</inertial>
	</link>
	<link name="link2">
		<visual>
			<geometry>
				<mesh filename="package://meshes/xarm6/visual/link2.stl"></mesh>
			</geometry>
			<origin rpy="0 0 0" xyz="0 0 0"></origin>
			<material name="Yellow"></material>
		</visual>
		<collision>
			<geometry>
				<sphere radius="0.079943"></sphere>
			</geometry>
			<origin xyz="0.0004846486686667685 -0.12591968388899877 0.011024136471449867" rpy="0 0 0"></origin>
		</collision>
		<collision>
			<geometry>
				<sphere radius="0.075052"></sphere>
			</geometry>
			<origin xyz="0.004889648668666768 -0.09484068388899877 0.07422213647144987" rpy="0 0 0"></origin>
		</collision>
		<collision>
			<geometry>
				<sphere radius="0.082253"></sphere>
			</geometry>
			<origin xyz="0.007262648668666768 -0.22533068388899877 -0.006941863528550134" rpy="0 0 0"></origin>
		</collision>
		<collision>
			<geometry>
				<sphere radius="0.072616"></sphere>
			</geometry>
			<origin xyz="0.051232648668666766 -0.2830816838889988 0.022236136471449865" rpy="0 0 0"></origin>
		</collision>
		<collision>
			<geometry>
				<sphere radius="0.063475"></sphere>
			</geometry>
			<origin xyz="0.03820264866866677 -0.28188768388899876 -0.026526863528550132" rpy="0 0 0"></origin>
		</collision>
		<collision>
			<geometry>
				<sphere radius="0.063614"></sphere>
			</geometry>
			<origin xyz="-0.004996351331333231 -0.028771683888998756 0.09146513647144985" rpy="0 0 0"></origin>
		</collision>
		<collision>
			<geometry>
				<sphere radius="0.056864"></sphere>
			</geometry>
			<origin xyz="0.0012426486686667668 0.006250316111001242 0.09591613647144986" rpy="0 0 0"></origin>
		</collision>
		<inertial>
			<origin rpy="0 0 0" xyz="0.03531 -0.21398 0.03386"></origin>
			<mass value="1.71"></mass>
			<inertia ixx="0.0248674" ixy="-0.00430651" ixz="-0.00067797" iyy="0.00485548" iyz="0.00457245" izz="0.02387827"></inertia>
		</inertial>
	</link>
	<link name="link3">
		<visual>
			<geometry>
				<mesh filename="package://meshes/xarm6/visual/link3.stl"></mesh>
			</geometry>
			<origin rpy="0 0 0" xyz="0 0 0"></origin>
			<material name="Blue"></material>
		</visual>
		<collision>
			<geometry>
				<sphere radius="0.063839"></sphere>
			</geometry>
			<origin xyz="0.07742532954927492 0.13147391996657287 -9.572208773333396e-05" rpy="0 0 0"></origin>
		</collision>
		<collision>
			<geometry>
				<sphere radius="0.070313"></sphere>
			</geometry>
			<origin xyz="0.07790832954927492 0.08982891996657286 0.015441277912266668" rpy="0 0 0"></origin>
		</collision>
		<collision>
			<geometry>
				<sphere radius="0.068698"></sphere>
			</geometry>
			<origin xyz="0.06986132954927492 0.07023191996657287 0.06643127791226666" rpy="0 0 0"></origin>
		</collision>
		<collision>
			<geometry>
				<sphere radius="0.06012"></sphere>
			</geometry>
			<origin xyz="0.020474329549274913 0.027930919966572862 0.08288827791226666" rpy="0 0 0"></origin>
		</collision>
		<collision>
			<geometry>
				<sphere radius="0.056565"></sphere>
			</geometry>
			<origin xyz="0.004089329549274913 -0.0004330800334271384 0.08665127791226668" rpy="0 0 0"></origin>
		</collision>
		<inertial>
			<origin rpy="0 0 0" xyz="0.06781 0.10749 0.01457"></origin>
			<mass value="1.384"></mass>
			<inertia ixx="0.0053694" ixy="0.0014185" ixz="-0.00092094" iyy="0.0032423" iyz="-0.00169178" izz="0.00501731"></inertia>
		</inertial>
	</link>
	<link name="link4">
		<visual>
			<geometry>
				<mesh filename="package://meshes/xarm6/visual/link4.stl"></mesh>
			</geometry>
			<origin rpy="0 0 0" xyz="0 0 0"></origin>
			<material name="Green"></material>
		</visual>
		<collision>
			<geometry>
				<sphere radius="0.067822"></sphere>
			</geometry>
			<origin xyz="0.0004097243993505716 0.049360182250559326 -0.006826227078647537" rpy="0 0 0"></origin>
		</collision>
		<collision>
			<geometry>
				<sphere radius="0.057577"></sphere>
			</geometry>
			<origin xyz="-0.0007392756006494285 0.001732182250559322 -0.14638022707864756" rpy="0 0 0"></origin>
		</collision>
		<collision>
			<geometry>
				<sphere radius="0.054549"></sphere>
			</geometry>
			<origin xyz="-0.0029792756006494286 0.030038182250559323 -0.12937522707864754" rpy="0 0 0"></origin>
		</collision>
		<collision>
			<geometry>
				<sphere radius="0.04567"></sphere>
			</geometry>
			<origin xyz="-0.014414275600649428 0.06287118225055932 -0.07978522707864755" rpy="0 0 0"></origin>
		</collision>
		<collision>
			<geometry>
				<sphere radius="0.044542"></sphere>
			</geometry>
			<origin xyz="0.01844272439935057 0.06017418225055932 -0.08541022707864754" rpy="0 0 0"></origin>
		</collision>
		<inertial>
			<origin rpy="0 0 0" xyz="-0.00021 0.02578 -0.02538"></origin>
			<mass value="1.115"></mass>
			<inertia ixx="0.00439263" ixy="5.028E-05" ixz="1.374E-05" iyy="0.0040077" iyz="0.00045338" izz="0.00110321"></inertia>
		</inertial>
	</link>
	<link name="link5">
		<visual>
			<geometry>
				<mesh filename="package://meshes/xarm6/visual/link5.stl"></mesh>
			</geometry>
			<origin rpy="0 0 0" xyz="0 0 0"></origin>
			<material name="Red"></material>
		</visual>
		<collision>
			<geometry>
				<sphere radius="0.069299"></sphere>
			</geometry>
			<origin xyz="0.0745638828613345 0.018523314638406632 0.0013069792150475785" rpy="0 0 0"></origin>
		</collision>
		<collision>
			<geometry>
				<sphere radius="0.058218"></sphere>
			</geometry>
			<origin xyz="0.008933882861334497 -0.0026086853615933693 0.02461197921504758" rpy="0 0 0"></origin>
		</collision>
		<inertial>
			<origin rpy="0 0 0" xyz="0.05428 0.01781 0.00543"></origin>
			<mass value="1.275"></mass>
			<inertia ixx="0.001202758" ixy="0.000492428" ixz="-0.00039147" iyy="0.0022876" iyz="-1.235E-04" izz="0.0026866"></inertia>
		</inertial>
	</link>
	<link name="link6">
		<visual>
			<geometry>
				<mesh filename="package://meshes/xarm6/visual/link6.stl"></mesh>
			</geometry>
			<origin rpy="0 0 0" xyz="0 0 0"></origin>
			<material name="Silver"></material>
		</visual>
		<collision>
			<geometry>
				<sphere radius="0.043027"></sphere>
			</geometry>
			<origin xyz="0.00012597950081289058 0.002432858134851147 -0.014535271939794769" rpy="0 0 0"></origin>
		</collision>
		<collision>
			<geometry>
				<sphere radius="0.041712"></sphere>
			</geometry>
			<origin xyz="-0.0011100204991871094 -0.014904141865148853 -0.014396271939794768" rpy="0 0 0"></origin>
		</collision>
		<inertial>
			<origin rpy="0 0 0" xyz="0 0.00064 -0.00952"></origin>
			<mass value="0.1096"></mass>
			<inertia ixx="4.5293E-05" ixy="0" ixz="0" iyy="4.8111E-05" iyz="0" izz="7.9715E-05"></inertia>
		</inertial>
	</link>
	<joint name="joint1" type="revolute">
		<parent link="link_base"></parent>
		<child link="link1"></child>
		<origin rpy="0 0 0" xyz="0 0 0.267"></origin>
		<axis xyz="0 0 1"></axis>
		<limit effort="50.0" lower="-6.28318530718" upper="6.28318530718" velocity="3.14"></limit>
		<dynamics damping="1.0" friction="1.0"></dynamics>
	</joint>
	<joint name="joint2" type="revolute">
		<parent link="link1"></parent>
		<child link="link2"></child>
		<origin rpy="-1.5708 0 0" xyz="0 0 0"></origin>
		<axis xyz="0 0 1"></axis>
		<limit effort="50.0" lower="-2.059" upper="2.0944" velocity="3.14"></limit>
		<dynamics damping="1.0" friction="1.0"></dynamics>
	</joint>
	<joint name="joint3" type="revolute">
		<parent link="link2"></parent>
		<child link="link3"></child>
		<origin rpy="0 0 0" xyz="0.0535 -0.2845 0"></origin>
		<axis xyz="0 0 1"></axis>
		<limit effort="32.0" lower="-3.927" upper="0.19198" velocity="3.14"></limit>
		<dynamics damping="1.0" friction="1.0"></dynamics>
	</joint>
	<joint name="joint4" type="revolute">
		<parent link="link3"></parent>
		<child link="link4"></child>
		<origin rpy="-1.5708 0 0" xyz="0.0775 0.3425 0"></origin>
		<axis xyz="0 0 1"></axis>
		<limit effort="32.0" lower="-6.28318530718" upper="6.28318530718" velocity="3.14"></limit>
		<dynamics damping="1.0" friction="1.0"></dynamics>
	</joint>
	<joint name="joint5" type="revolute">
		<parent link="link4"></parent>
		<child link="link5"></child>
		<origin rpy="1.5708 0 0" xyz="0 0 0"></origin>
		<axis xyz="0 0 1"></axis>
		<limit effort="32.0" lower="-1.69297" upper="3.14159265359" velocity="3.14"></limit>
		<dynamics damping="1.0" friction="1.0"></dynamics>
	</joint>
	<joint name="joint6" type="revolute">
		<parent link="link5"></parent>
		<child link="link6"></child>
		<origin rpy="-1.5708 0 0" xyz="0.076 0.097 0"></origin>
		<axis xyz="0 0 1"></axis>
		<limit effort="20.0" lower="-6.28318530718" upper="6.28318530718" velocity="3.14"></limit>
		<dynamics damping="1.0" friction="1.0"></dynamics>
	</joint>

	<link name="xarm6_ee_stick">
		<visual>
		<geometry>
			<cylinder length="0.173" radius="0.005"/>
		</geometry>
		<origin rpy="0 0 0" xyz="0 0 0.0865"/>
		<material name="Purple"/>
		</visual>

		<collision>
			<geometry>
				<sphere radius="0.005"></sphere>
			</geometry>
			<origin xyz="0.0 0.0 0.0" rpy="0 0 0"></origin>
		</collision>

		<collision>
			<geometry>
				<sphere radius="0.005"></sphere>
			</geometry>
			<origin xyz="0.0 0.0 0.005" rpy="0 0 0"></origin>
		</collision>

		<collision>
			<geometry>
				<sphere radius="0.005"></sphere>
			</geometry>
			<origin xyz="0.0 0.0 0.01" rpy="0 0 0"></origin>
		</collision>

		<collision>
			<geometry>
				<sphere radius="0.005"></sphere>
			</geometry>
			<origin xyz="0.0 0.0 0.015" rpy="0 0 0"></origin>
		</collision>

		<collision>
			<geometry>
				<sphere radius="0.005"></sphere>
			</geometry>
			<origin xyz="0.0 0.0 0.020" rpy="0 0 0"></origin>
		</collision>

		<collision>
			<geometry>
				<sphere radius="0.005"></sphere>
			</geometry>
			<origin xyz="0.0 0.0 0.025" rpy="0 0 0"></origin>
		</collision>

		<collision>
			<geometry>
				<sphere radius="0.005"></sphere>
			</geometry>
			<origin xyz="0.0 0.0 0.03" rpy="0 0 0"></origin>
		</collision>

		<collision>
			<geometry>
				<sphere radius="0.005"></sphere>
			</geometry>
			<origin xyz="0.0 0.0 0.035" rpy="0 0 0"></origin>
		</collision>

		<collision>
			<geometry>
				<sphere radius="0.005"></sphere>
			</geometry>
			<origin xyz="0.0 0.0 0.04" rpy="0 0 0"></origin>
		</collision>

		<collision>
			<geometry>
				<sphere radius="0.005"></sphere>
			</geometry>
			<origin xyz="0.0 0.0 0.045" rpy="0 0 0"></origin>
		</collision>

		<collision>
			<geometry>
				<sphere radius="0.005"></sphere>
			</geometry>
			<origin xyz="0.0 0.0 0.05" rpy="0 0 0"></origin>
		</collision>

		<collision>
			<geometry>
				<sphere radius="0.005"></sphere>
			</geometry>
			<origin xyz="0.0 0.0 0.055" rpy="0 0 0"></origin>
		</collision>

		<collision>
			<geometry>
				<sphere radius="0.005"></sphere>
			</geometry>
			<origin xyz="0.0 0.0 0.06" rpy="0 0 0"></origin>
		</collision>

		<collision>
			<geometry>
				<sphere radius="0.005"></sphere>
			</geometry>
			<origin xyz="0.0 0.0 0.065" rpy="0 0 0"></origin>
		</collision>

		<collision>
			<geometry>
				<sphere radius="0.005"></sphere>
			</geometry>
			<origin xyz="0.0 0.0 0.07" rpy="0 0 0"></origin>
		</collision>

		<collision>
			<geometry>
				<sphere radius="0.005"></sphere>
			</geometry>
			<origin xyz="0.0 0.0 0.075" rpy="0 0 0"></origin>
		</collision>

		<collision>
			<geometry>
				<sphere radius="0.005"></sphere>
			</geometry>
			<origin xyz="0.0 0.0 0.08" rpy="0 0 0"></origin>
		</collision>

		<collision>
			<geometry>
				<sphere radius="0.005"></sphere>
			</geometry>
			<origin xyz="0.0 0.0 0.09" rpy="0 0 0"></origin>
		</collision>

		<collision>
			<geometry>
				<sphere radius="0.005"></sphere>
			</geometry>
			<origin xyz="0.0 0.0 0.095" rpy="0 0 0"></origin>
		</collision>

		<collision>
			<geometry>
				<sphere radius="0.005"></sphere>
			</geometry>
			<origin xyz="0.0 0.0 0.1" rpy="0 0 0"></origin>
		</collision>

		<collision>
			<geometry>
				<sphere radius="0.005"></sphere>
			</geometry>
			<origin xyz="0.0 0.0 0.105" rpy="0 0 0"></origin>
		</collision>

		<collision>
			<geometry>
				<sphere radius="0.005"></sphere>
			</geometry>
			<origin xyz="0.0 0.0 0.11" rpy="0 0 0"></origin>
		</collision>

		<collision>
			<geometry>
				<sphere radius="0.005"></sphere>
			</geometry>
			<origin xyz="0.0 0.0 0.115" rpy="0 0 0"></origin>
		</collision>

		<collision>
			<geometry>
				<sphere radius="0.005"></sphere>
			</geometry>
			<origin xyz="0.0 0.0 0.120" rpy="0 0 0"></origin>
		</collision>

		<collision>
			<geometry>
				<sphere radius="0.005"></sphere>
			</geometry>
			<origin xyz="0.0 0.0 0.125" rpy="0 0 0"></origin>
		</collision>

		<collision>
			<geometry>
				<sphere radius="0.005"></sphere>
			</geometry>
			<origin xyz="0.0 0.0 0.13" rpy="0 0 0"></origin>
		</collision>

		<collision>
			<geometry>
				<sphere radius="0.005"></sphere>
			</geometry>
			<origin xyz="0.0 0.0 0.135" rpy="0 0 0"></origin>
		</collision>

		<collision>
			<geometry>
				<sphere radius="0.005"></sphere>
			</geometry>
			<origin xyz="0.0 0.0 0.14" rpy="0 0 0"></origin>
		</collision>

		<collision>
			<geometry>
				<sphere radius="0.005"></sphere>
			</geometry>
			<origin xyz="0.0 0.0 0.145" rpy="0 0 0"></origin>
		</collision>

		<collision>
			<geometry>
				<sphere radius="0.005"></sphere>
			</geometry>
			<origin xyz="0.0 0.0 0.15" rpy="0 0 0"></origin>
		</collision>

		<collision>
			<geometry>
				<sphere radius="0.005"></sphere>
			</geometry>
			<origin xyz="0.0 0.0 0.155" rpy="0 0 0"></origin>
		</collision>

		<collision>
			<geometry>
				<sphere radius="0.005"></sphere>
			</geometry>
			<origin xyz="0.0 0.0 0.16" rpy="0 0 0"></origin>
		</collision>

		<collision>
			<geometry>
				<sphere radius="0.005"></sphere>
			</geometry>
			<origin xyz="0.0 0.0 0.165" rpy="0 0 0"></origin>
		</collision>

		<collision>
			<geometry>
				<sphere radius="0.005"></sphere>
			</geometry>
			<origin xyz="0.0 0.0 0.17" rpy="0 0 0"></origin>
		</collision>

		<collision>
			<geometry>
				<sphere radius="0.005"></sphere>
			</geometry>
			<origin xyz="0.0 0.0 0.175" rpy="0 0 0"></origin>
		</collision>
	</link>
	<joint name="xarm6_ee_stick_joint" type="fixed">
		<origin rpy="0 0 0" xyz="0 0 -0.015"/>
		<parent link="link6"/>
		<child link="xarm6_ee_stick"/>
		<axis xyz="0 0 0"/>
	</joint>
	<link name="xarm6_ee_tip">
		<collision>
			<geometry>
				<sphere radius="0.01"></sphere>
			</geometry>
			<origin xyz="0.0 0.0 0.0" rpy="0 0 0"></origin>
		</collision>
	</link>
	<joint name="xarm6_ee_tip_joint" type="fixed">
		<origin rpy="0 0 0" xyz="0 0 0.173"/>
		<parent link="xarm6_ee_stick"/>
		<child link="xarm6_ee_tip"/>
		<axis xyz="0 0 0"/>
	</joint>


	<material name="Black">
		<color rgba="0.0 0.0 0.0 1.0"></color>
	</material>
	<material name="Red">
		<color rgba="0.85 0.19  0.21 1.0"></color>
	</material>
	<material name="Blue">
		<color rgba="0.28 0.52 0.92 1.0"></color>
	</material>
	<material name="Green">
		<color rgba="0.23 0.72 0.32 1.0"></color>
	</material>
	<material name="Yellow">
		<color rgba="0.95 0.76 0.05 1.0"></color>
	</material>
	<material name="White">
		<color rgba="1.0 1.0 1.0 1.0"></color>
	</material>
	<material name="Silver">
		<color rgba="0.753 0.753 0.753 1.0"></color>
	</material>
	<transmission name="tran1">
		<type>transmission_interface/SimpleTransmission</type>
		<joint name="joint1">
			<hardwareInterface>hardware_interface/PositionJointInterface</hardwareInterface>
		</joint>
		<actuator name="motor1">
			<hardwareInterface>hardware_interface/PositionJointInterface</hardwareInterface>
			<mechanicalReduction>100</mechanicalReduction>
		</actuator>
	</transmission>
	<transmission name="tran2">
		<type>transmission_interface/SimpleTransmission</type>
		<joint name="joint2">
			<hardwareInterface>hardware_interface/PositionJointInterface</hardwareInterface>
		</joint>
		<actuator name="motor2">
			<hardwareInterface>hardware_interface/PositionJointInterface</hardwareInterface>
			<mechanicalReduction>100</mechanicalReduction>
		</actuator>
	</transmission>
	<transmission name="tran3">
		<type>transmission_interface/SimpleTransmission</type>
		<joint name="joint3">
			<hardwareInterface>hardware_interface/PositionJointInterface</hardwareInterface>
		</joint>
		<actuator name="motor3">
			<hardwareInterface>hardware_interface/PositionJointInterface</hardwareInterface>
			<mechanicalReduction>100</mechanicalReduction>
		</actuator>
	</transmission>
	<transmission name="tran4">
		<type>transmission_interface/SimpleTransmission</type>
		<joint name="joint4">
			<hardwareInterface>hardware_interface/PositionJointInterface</hardwareInterface>
		</joint>
		<actuator name="motor3">
			<hardwareInterface>hardware_interface/PositionJointInterface</hardwareInterface>
			<mechanicalReduction>100</mechanicalReduction>
		</actuator>
	</transmission>
	<transmission name="tran5">
		<type>transmission_interface/SimpleTransmission</type>
		<joint name="joint5">
			<hardwareInterface>hardware_interface/PositionJointInterface</hardwareInterface>
		</joint>
		<actuator name="motor5">
			<hardwareInterface>hardware_interface/PositionJointInterface</hardwareInterface>
			<mechanicalReduction>100</mechanicalReduction>
		</actuator>
	</transmission>
	<transmission name="tran6">
		<type>transmission_interface/SimpleTransmission</type>
		<joint name="joint6">
			<hardwareInterface>hardware_interface/PositionJointInterface</hardwareInterface>
		</joint>
		<actuator name="motor6">
			<hardwareInterface>hardware_interface/PositionJointInterface</hardwareInterface>
			<mechanicalReduction>100</mechanicalReduction>
		</actuator>
	</transmission>
</robot>